Workbook

Sheet Lipid_Params 
A1: Name | B1: Lipid Mol Weight | C1: Postive N per lipid (used in NP ratio calculation)
A2: DOTAP | B2: 698.54 | C2: 1
A3: DSPC | B3: 790.145 | C3: 1
A4: 18PG | B4: 797.026 | C4: 0
A5: DOPE | B5: 744.034 | C5: 1
A6: DDAB | B6: 630.95 | C6: 1
A7: 14PA | B7: 614.767 | C7: 0
A8: 18BMP | B8: 792.075 | C8: 0
A10: SM102 | B10: 710.17 | C10: 1
A11: Dlin | B11: 642.09 | C11: 1
A12: ALC0315 | B12: 766.29 | C12: 1
A14: Chol | B14: 386.654 | C14: 0
A15: DMG_PEG | B15: 2500 | C15: 0

Sheet Formulations
A1: Date & Person: | B1: Units
A2: *drag column to right to create more formulations*
A3: Relative Formulation Label | C3: BO | D3: BO | E3: BO | F3: BO | G3: BO | H3: BO | I3: BO | J3: BO | K3: BO | L3: BO | M3: BO | N3: BO | O3: DA | P3: DA | Q3: DA | R3: DA | S3: DA | T3: DA | U3: DA | V3: DA | W3: DA | X3: DA | Y3: DA | Z3: DA | AA3: NSGAII | AB3: NSGAII | AC3: NSGAII | AD3: NSGAII | AE3: NSGAII | AF3: NSGAII | AG3: NSGAII | AH3: NSGAII | AI3: NSGAII | AJ3: NSGAII | AK3: NSGAII | AL3: NSGAII
A4: Notes / Identifiers
A5: Formulation parameters
A6: Ionizable Lipid Name | C6: Dlin | D6: Dlin | E6: Dlin | F6: Dlin | G6: Dlin | H6: Dlin | I6: Dlin | J6: Dlin | K6: Dlin | L6: Dlin | M6: Dlin | N6: Dlin | O6: Dlin | P6: Dlin | Q6: Dlin | R6: Dlin | S6: Dlin | T6: Dlin | U6: Dlin | V6: Dlin | W6: Dlin | X6: Dlin | Y6: Dlin | Z6: Dlin | AA6: Dlin | AB6: Dlin | AC6: Dlin | AD6: Dlin | AE6: Dlin | AF6: Dlin | AG6: Dlin | AH6: Dlin | AI6: Dlin | AJ6: Dlin | AK6: Dlin | AL6: Dlin
A7: Helper Lipid Name | C7: DSPC | D7: DSPC | E7: DSPC | F7: DSPC | G7: DSPC | H7: DSPC | I7: DSPC | J7: DSPC | K7: DSPC | L7: DSPC | M7: DSPC | N7: DSPC | O7: DSPC | P7: DSPC | Q7: DSPC | R7: DSPC | S7: DSPC | T7: DSPC | U7: DSPC | V7: DSPC | W7: DSPC | X7: DSPC | Y7: DSPC | Z7: DSPC | AA7: DSPC | AB7: DSPC | AC7: DSPC | AD7: DSPC | AE7: DSPC | AF7: DSPC | AG7: DSPC | AH7: DSPC | AI7: DSPC | AJ7: DSPC | AK7: DSPC | AL7: DSPC
A8: Cholesterol Lipid Name | C8: Chol | D8: Chol | E8: Chol | F8: Chol | G8: Chol | H8: Chol | I8: Chol | J8: Chol | K8: Chol | L8: Chol | M8: Chol | N8: Chol | O8: Chol | P8: Chol | Q8: Chol | R8: Chol | S8: Chol | T8: Chol | U8: Chol | V8: Chol | W8: Chol | X8: Chol | Y8: Chol | Z8: Chol | AA8: Chol | AB8: Chol | AC8: Chol | AD8: Chol | AE8: Chol | AF8: Chol | AG8: Chol | AH8: Chol | AI8: Chol | AJ8: Chol | AK8: Chol | AL8: Chol
A9: PEG Lipid Name | C9: DMG_PEG | D9: DMG_PEG | E9: DMG_PEG | F9: DMG_PEG | G9: DMG_PEG | H9: DMG_PEG | I9: DMG_PEG | J9: DMG_PEG | K9: DMG_PEG | L9: DMG_PEG | M9: DMG_PEG | N9: DMG_PEG | O9: DMG_PEG | P9: DMG_PEG | Q9: DMG_PEG | R9: DMG_PEG | S9: DMG_PEG | T9: DMG_PEG | U9: DMG_PEG | V9: DMG_PEG | W9: DMG_PEG | X9: DMG_PEG | Y9: DMG_PEG | Z9: DMG_PEG | AA9: DMG_PEG | AB9: DMG_PEG | AC9: DMG_PEG | AD9: DMG_PEG | AE9: DMG_PEG | AF9: DMG_PEG | AG9: DMG_PEG | AH9: DMG_PEG | AI9: DMG_PEG | AJ9: DMG_PEG | AK9: DMG_PEG | AL9: DMG_PEG
A10: NP Ratio | C10: 13.884 | D10: 11.541 | E10: 24.538 | F10: 25.035 | G10: 24.432 | H10: 20.823 | I10: 23.082 | J10: 29.833 | K10: 27.708 | L10: 9.013 | M10: 8.403 | N10: 28.521 | O10: 7.005 | P10: 6.992 | Q10: 7.004 | R10: 6.979 | S10: 6.982 | T10: 7.021 | U10: 6.976 | V10: 6.957 | W10: 6.952 | X10: 6.947 | Y10: 6.987 | Z10: 7.007 | AA10: 5.854 | AB10: 4.457 | AC10: 5.101 | AD10: 7.198 | AE10: 4.029 | AF10: 4.007 | AG10: 6.95 | AH10: 6.978 | AI10: 4.446 | AJ10: 5.838 | AK10: 5.354 | AL10: 4.451
A11: (IL+HL)% (molar) | C11: 58.286 | D11: 56.684 | E11: 53.219 | F11: 52.217 | G11: 60.52 | H11: 55.632 | I11: 52.825 | J11: 57.109 | K11: 57.13 | L11: 54.795 | M11: 55.035 | N11: 61.229 | O11: 52.458 | P11: 52.462 | Q11: 52.46 | R11: 52.443 | S11: 52.406 | T11: 52.372 | U11: 52.362 | V11: 52.409 | W11: 52.456 | X11: 52.444 | Y11: 52.449 | Z11: 52.445 | AA11: 67.696 | AB11: 67.866 | AC11: 65.162 | AD11: 51.761 | AE11: 70.305 | AF11: 52.423 | AG11: 52.426 | AH11: 52.459 | AI11: 67.624 | AJ11: 54.443 | AK11: 54.411 | AL11: 67.724
A12: HL/(IL+HL)% | C12: 43.775 | D12: 26.325 | E12: 26.651 | F12: 30.138 | G12: 29.813 | H12: 25.229 | I12: 53.228 | J12: 62.083 | K12: 21.712 | L12: 26.844 | M12: 48.819 | N12: 55.843 | O12: 25.681 | P12: 26.234 | Q12: 25.588 | R12: 25.695 | S12: 25.821 | T12: 26.099 | U12: 26.025 | V12: 25.635 | W12: 26.178 | X12: 26.379 | Y12: 26.277 | Z12: 25.994 | AA12: 83.019 | AB12: 68.051 | AC12: 0.498 | AD12: 26.326 | AE12: 56.494 | AF12: 54.017 | AG12: 67.805 | AH12: 26.388 | AI12: 70.018 | AJ12: 83.087 | AK12: 54.055 | AL12: 72.124
A13: PEG/(Chol+PEG)% | C13: 3.214 | D13: 6.424 | E13: 25.566 | F13: 3.99 | G13: 4.804 | H13: 6.992 | I13: 4.478 | J13: 4.113 | K13: 1.593 | L13: 6.764 | M13: 3.845 | N13: 2.578 | O13: 0.874 | P13: 0.944 | Q13: 0.938 | R13: 0.611 | S13: 0.948 | T13: 0.946 | U13: 0.656 | V13: 0.765 | W13: 0.942 | X13: 0.943 | Y13: 0.947 | Z13: 0.623 | AA13: 6.379 | AB13: 30.795 | AC13: 11.381 | AD13: 0.642 | AE13: 18.092 | AF13: 9.936 | AG13: 2.964 | AH13: 7.463 | AI13: 24.983 | AJ13: 4.888 | AK13: 4.858 | AL13: 18.398
A14: Final NP Nucleic Acid Conc | B14: ug/mL | C14: 50 | D14: 50 | E14: 50 | F14: 50 | G14: 50 | H14: 50 | I14: 50 | J14: 50 | K14: 50 | L14: 50 | M14: 50 | N14: 50 | O14: 50 | P14: 50 | Q14: 50 | R14: 50 | S14: 50 | T14: 50 | U14: 50 | V14: 50 | W14: 50 | X14: 50 | Y14: 50 | Z14: 50 | AA14: 50 | AB14: 50 | AC14: 50 | AD14: 50 | AE14: 50 | AF14: 50 | AG14: 50 | AH14: 50 | AI14: 50 | AJ14: 50 | AK14: 50 | AL14: 50 | AM14: 50 | AN14: 50 | AO14: 50 | AP14: 50 | AQ14: 50 | AR14: 50 | AS14: 50 | AT14: 50 | AU14: 50 | AV14: 50 | AW14: 50 | AX14: 50 | AY14: 50 | AZ14: 50 | BA14: 50 | BB14: 50 | BC14: 50 | BD14: 50 | BE14: 50 | BF14: 50 | BG14: 50 | BH14: 50 | BI14: 50 | BJ14: 50 | BK14: 50 | BL14: 50 | BM14: 50 | BN14: 50 | BO14: 50 | BP14: 50 | BQ14: 50 | BR14: 50 | BS14: 50 | BT14: 50 | BU14: 50 | BV14: 50 | BW14: 50 | BX14: 50 | BY14: 50 | BZ14: 50 | CA14: 50 | CB14: 50 | CC14: 50 | CD14: 50 | CE14: 50 | CF14: 50 | CG14: 50 | CH14: 50 | CI14: 50 | CJ14: 50 | CK14: 50 | CL14: 50 | CM14: 50 | CN14: 50 | CO14: 50 | CP14: 50 | CQ14: 50 | CR14: 50 | CS14: 50 | CT14: 50 | CU14: 50 | CV14: 50 | CW14: 50 | CX14: 50 | CY14: 50 | CZ14: 50 | DA14: 50 | DB14: 50 | DC14: 50 | DD14: 50 | DE14: 50 | DF14: 50 | DG14: 50 | DH14: 50 | DI14: 50 | DJ14: 50 | DK14: 50 | DL14: 50 | DM14: 50 | DN14: 50 | DO14: 50 | DP14: 50 | DQ14: 50 | DR14: 50 | DS14: 50 | DT14: 50 | DU14: 50 | DV14: 50 | DW14: 50 | DX14: 50 | DY14: 50 | DZ14: 50 | EA14: 50 | EB14: 50 | EC14: 50 | ED14: 50 | EE14: 50 | EF14: 50 | EG14: 50 | EH14: 50 | EI14: 50 | EJ14: 50
A15: Total NP Volume | B15: ul | C15: 100 | D15: 100 | E15: 100 | F15: 100 | G15: 100 | H15: 100 | I15: 100 | J15: 100 | K15: 100 | L15: 100 | M15: 100 | N15: 100 | O15: 100 | P15: 100 | Q15: 100 | R15: 100 | S15: 100 | T15: 100 | U15: 100 | V15: 100 | W15: 100 | X15: 100 | Y15: 100 | Z15: 100 | AA15: 100 | AB15: 100 | AC15: 100 | AD15: 100 | AE15: 100 | AF15: 100 | AG15: 100 | AH15: 100 | AI15: 100 | AJ15: 100 | AK15: 100 | AL15: 100 | AM15: 100 | AN15: 100 | AO15: 100 | AP15: 100 | AQ15: 100 | AR15: 100 | AS15: 100 | AT15: 100 | AU15: 100 | AV15: 100 | AW15: 100 | AX15: 100 | AY15: 100 | AZ15: 100 | BA15: 100 | BB15: 100 | BC15: 100 | BD15: 100 | BE15: 100 | BF15: 100 | BG15: 100 | BH15: 100 | BI15: 100 | BJ15: 100 | BK15: 100 | BL15: 100 | BM15: 100 | BN15: 100 | BO15: 100 | BP15: 100 | BQ15: 100 | BR15: 100 | BS15: 100 | BT15: 100 | BU15: 100 | BV15: 100 | BW15: 100 | BX15: 100 | BY15: 100 | BZ15: 100 | CA15: 100 | CB15: 100 | CC15: 100 | CD15: 100 | CE15: 100 | CF15: 100 | CG15: 100 | CH15: 100 | CI15: 100 | CJ15: 100 | CK15: 100 | CL15: 100 | CM15: 100 | CN15: 100 | CO15: 100 | CP15: 100 | CQ15: 100 | CR15: 100 | CS15: 100 | CT15: 100 | CU15: 100 | CV15: 100 | CW15: 100 | CX15: 100 | CY15: 100 | CZ15: 100 | DA15: 100 | DB15: 100 | DC15: 100 | DD15: 100 | DE15: 100 | DF15: 100 | DG15: 100 | DH15: 100 | DI15: 100 | DJ15: 100 | DK15: 100 | DL15: 100 | DM15: 100 | DN15: 100 | DO15: 100 | DP15: 100 | DQ15: 100 | DR15: 100 | DS15: 100 | DT15: 100 | DU15: 100 | DV15: 100 | DW15: 100 | DX15: 100 | DY15: 100 | DZ15: 100 | EA15: 100 | EB15: 100 | EC15: 100 | ED15: 100 | EE15: 100 | EF15: 100 | EG15: 100 | EH15: 100 | EI15: 100 | EJ15: 100
A18: IL:HL ratio | C18: =(1-(C12/100))/(C12/100) | D18: =(1-(D12/100))/(D12/100) | E18: =(1-(E12/100))/(E12/100) | F18: =(1-(F12/100))/(F12/100) | G18: =(1-(G12/100))/(G12/100) | H18: =(1-(H12/100))/(H12/100) | I18: =(1-(I12/100))/(I12/100) | J18: =(1-(J12/100))/(J12/100) | ... EJ18: =(1-(EJ12/100))/(EJ12/100)
A19: Chol:PEG ratio | C19: =(1-(C13/100))/(C13/100) | D19: =(1-(D13/100))/(D13/100) | E19: =(1-(E13/100))/(E13/100) | F19: =(1-(F13/100))/(F13/100) | G19: =(1-(G13/100))/(G13/100) | H19: =(1-(H13/100))/(H13/100) | I19: =(1-(I13/100))/(I13/100) | J19: =(1-(J13/100))/(J13/100) | ... EJ19: =(1-(EJ13/100))/(EJ13/100)
A21: Chemical Properties
A22: Ionizable Lipid Mol Weight | B22: g/mol | C22: =VLOOKUP(C6,'Lipid_Params '!$A:$C,2,FALSE) | D22: =VLOOKUP(D6,'Lipid_Params '!$A:$C,2,FALSE) | E22: =VLOOKUP(E6,'Lipid_Params '!$A:$C,2,FALSE) | F22: =VLOOKUP(F6,'Lipid_Params '!$A:$C,2,FALSE) | G22: =VLOOKUP(G6,'Lipid_Params '!$A:$C,2,FALSE) | H22: =VLOOKUP(H6,'Lipid_Params '!$A:$C,2,FALSE) | I22: =VLOOKUP(I6,'Lipid_Params '!$A:$C,2,FALSE) | J22: =VLOOKUP(J6,'Lipid_Params '!$A:$C,2,FALSE) | ... EJ22: =VLOOKUP(EJ6,'Lipid_Params '!$A:$C,2,FALSE)
A23: Helper Lipid Mol Weight | B23: g/mol | C23: =VLOOKUP(C7,'Lipid_Params '!$A:$C,2,FALSE) | D23: =VLOOKUP(D7,'Lipid_Params '!$A:$C,2,FALSE) | E23: =VLOOKUP(E7,'Lipid_Params '!$A:$C,2,FALSE) | F23: =VLOOKUP(F7,'Lipid_Params '!$A:$C,2,FALSE) | G23: =VLOOKUP(G7,'Lipid_Params '!$A:$C,2,FALSE) | H23: =VLOOKUP(H7,'Lipid_Params '!$A:$C,2,FALSE) | I23: =VLOOKUP(I7,'Lipid_Params '!$A:$C,2,FALSE) | J23: =VLOOKUP(J7,'Lipid_Params '!$A:$C,2,FALSE) | ... EJ23: =VLOOKUP(EJ7,'Lipid_Params '!$A:$C,2,FALSE)
A24: Cholesterol Mol Weight | B24: g/mol | C24: =VLOOKUP(C8,'Lipid_Params '!$A:$C,2,FALSE) | D24: =VLOOKUP(D8,'Lipid_Params '!$A:$C,2,FALSE) | E24: =VLOOKUP(E8,'Lipid_Params '!$A:$C,2,FALSE) | F24: =VLOOKUP(F8,'Lipid_Params '!$A:$C,2,FALSE) | G24: =VLOOKUP(G8,'Lipid_Params '!$A:$C,2,FALSE) | H24: =VLOOKUP(H8,'Lipid_Params '!$A:$C,2,FALSE) | I24: =VLOOKUP(I8,'Lipid_Params '!$A:$C,2,FALSE) | J24: =VLOOKUP(J8,'Lipid_Params '!$A:$C,2,FALSE) | ... EJ24: =VLOOKUP(EJ8,'Lipid_Params '!$A:$C,2,FALSE)
A25: DMG-PEG Mol Weight | B25: g/mol | C25: =VLOOKUP(C9,'Lipid_Params '!$A:$C,2,FALSE) | D25: =VLOOKUP(D9,'Lipid_Params '!$A:$C,2,FALSE) | E25: =VLOOKUP(E9,'Lipid_Params '!$A:$C,2,FALSE) | F25: =VLOOKUP(F9,'Lipid_Params '!$A:$C,2,FALSE) | G25: =VLOOKUP(G9,'Lipid_Params '!$A:$C,2,FALSE) | H25: =VLOOKUP(H9,'Lipid_Params '!$A:$C,2,FALSE) | I25: =VLOOKUP(I9,'Lipid_Params '!$A:$C,2,FALSE) | J25: =VLOOKUP(J9,'Lipid_Params '!$A:$C,2,FALSE) | ... EJ25: =VLOOKUP(EJ9,'Lipid_Params '!$A:$C,2,FALSE)
A26: Estimated # Phosphates in nucleic acids (used in NP ratio calculation) | B26: nmol/ug | C26: 3 | D26: 3 | E26: 3 | F26: 3 | G26: 3 | H26: 3 | I26: 3 | J26: 3 | K26: 3 | L26: 3 | M26: 3 | N26: 3 | O26: 3 | P26: 3 | Q26: 3 | R26: 3 | S26: 3 | T26: 3 | U26: 3 | V26: 3 | W26: 3 | X26: 3 | Y26: 3 | Z26: 3 | AA26: 3 | AB26: 3 | AC26: 3 | AD26: 3 | AE26: 3 | AF26: 3 | AG26: 3 | AH26: 3 | AI26: 3 | AJ26: 3 | AK26: 3 | AL26: 3 | AM26: 3 | AN26: 3 | AO26: 3 | AP26: 3 | AQ26: 3 | AR26: 3 | AS26: 3 | AT26: 3 | AU26: 3 | AV26: 3 | AW26: 3 | AX26: 3 | AY26: 3 | AZ26: 3 | BA26: 3 | BB26: 3 | BC26: 3 | BD26: 3 | BE26: 3 | BF26: 3 | BG26: 3 | BH26: 3 | BI26: 3 | BJ26: 3 | BK26: 3 | BL26: 3 | BM26: 3 | BN26: 3 | BO26: 3 | BP26: 3 | BQ26: 3 | BR26: 3 | BS26: 3 | BT26: 3 | BU26: 3 | BV26: 3 | BW26: 3 | BX26: 3 | BY26: 3 | BZ26: 3 | CA26: 3 | CB26: 3 | CC26: 3 | CD26: 3 | CE26: 3 | CF26: 3 | CG26: 3 | CH26: 3 | CI26: 3 | CJ26: 3 | CK26: 3 | CL26: 3 | CM26: 3 | CN26: 3 | CO26: 3 | CP26: 3 | CQ26: 3 | CR26: 3 | CS26: 3 | CT26: 3 | CU26: 3 | CV26: 3 | CW26: 3 | CX26: 3 | CY26: 3 | CZ26: 3 | DA26: 3 | DB26: 3 | DC26: 3 | DD26: 3 | DE26: 3 | DF26: 3 | DG26: 3 | DH26: 3 | DI26: 3 | DJ26: 3 | DK26: 3 | DL26: 3 | DM26: 3 | DN26: 3 | DO26: 3 | DP26: 3 | DQ26: 3 | DR26: 3 | DS26: 3 | DT26: 3 | DU26: 3 | DV26: 3 | DW26: 3 | DX26: 3 | DY26: 3 | DZ26: 3 | EA26: 3 | EB26: 3 | EC26: 3 | ED26: 3 | EE26: 3 | EF26: 3 | EG26: 3 | EH26: 3 | EI26: 3 | EJ26: 3
A27: Postive N per ionizable lipid (used in NP ratio calculation) | B27: mol/mol | C27: =VLOOKUP(C6,'Lipid_Params '!$A:$C,3,FALSE) | D27: =VLOOKUP(D6,'Lipid_Params '!$A:$C,3,FALSE) | E27: =VLOOKUP(E6,'Lipid_Params '!$A:$C,3,FALSE) | F27: =VLOOKUP(F6,'Lipid_Params '!$A:$C,3,FALSE) | G27: =VLOOKUP(G6,'Lipid_Params '!$A:$C,3,FALSE) | H27: =VLOOKUP(H6,'Lipid_Params '!$A:$C,3,FALSE) | I27: =VLOOKUP(I6,'Lipid_Params '!$A:$C,3,FALSE) | J27: =VLOOKUP(J6,'Lipid_Params '!$A:$C,3,FALSE) | ... EJ27: =VLOOKUP(EJ6,'Lipid_Params '!$A:$C,3,FALSE)
A28: Postive N per helper lipid (used in NP ratio calculation) | B28: mol/mol | C28: =VLOOKUP(C7,'Lipid_Params '!$A:$C,3,FALSE) | D28: =VLOOKUP(D7,'Lipid_Params '!$A:$C,3,FALSE) | E28: =VLOOKUP(E7,'Lipid_Params '!$A:$C,3,FALSE) | F28: =VLOOKUP(F7,'Lipid_Params '!$A:$C,3,FALSE) | G28: =VLOOKUP(G7,'Lipid_Params '!$A:$C,3,FALSE) | H28: =VLOOKUP(H7,'Lipid_Params '!$A:$C,3,FALSE) | I28: =VLOOKUP(I7,'Lipid_Params '!$A:$C,3,FALSE) | J28: =VLOOKUP(J7,'Lipid_Params '!$A:$C,3,FALSE) | ... EJ28: =VLOOKUP(EJ7,'Lipid_Params '!$A:$C,3,FALSE)
A30: Calculation
A31: helper lipid stock concentration (mM) | B31: mM | C31: =C55/C23*1000 | D31: =D55/D23*1000 | E31: =E55/E23*1000 | F31: =F55/F23*1000 | G31: =G55/G23*1000 | H31: =H55/H23*1000 | I31: =I55/I23*1000 | J31: =J55/J23*1000 | ... EJ31: =EJ55/EJ23*1000
A32: Ionizable Lipid mM | B32: mM | C32: =C54/C22*1000 | D32: =D54/D22*1000 | E32: =E54/E22*1000 | F32: =F54/F22*1000 | G32: =G54/G22*1000 | H32: =H54/H22*1000 | I32: =I54/I22*1000 | J32: =J54/J22*1000 | ... EJ32: =EJ54/EJ22*1000
A33: Cholesterol mM | B33: mM | C33: =C56/C24*1000 | D33: =D56/D24*1000 | E33: =E56/E24*1000 | F33: =F56/F24*1000 | G33: =G56/G24*1000 | H33: =H56/H24*1000 | I33: =I56/I24*1000 | J33: =J56/J24*1000 | ... EJ33: =EJ56/EJ24*1000
A34: DMG-PEG mM | B34: mM | C34: =C57/C25*1000 | D34: =D57/D25*1000 | E34: =E57/E25*1000 | F34: =F57/F25*1000 | G34: =G57/G25*1000 | H34: =H57/H25*1000 | I34: =I57/I25*1000 | J34: =J57/J25*1000 | ... EJ34: =EJ57/EJ25*1000
A36: Total Moles of Lipid in formulation | B36: nmoles | C36: =C37*C26*C10*100/(C27*C41+C28*C44) | D36: =D37*D26*D10*100/(D27*D41+D28*D44) | E36: =E37*E26*E10*100/(E27*E41+E28*E44) | F36: =F37*F26*F10*100/(F27*F41+F28*F44) | G36: =G37*G26*G10*100/(G27*G41+G28*G44) | H36: =H37*H26*H10*100/(H27*H41+H28*H44) | I36: =I37*I26*I10*100/(I27*I41+I28*I44) | J36: =J37*J26*J10*100/(J27*J41+J28*J44) | ... EJ36: =EJ37*EJ26*EJ10*100/(EJ27*EJ41+EJ28*EJ44)
A37: Total Nucleic Acid in formulation | B37: ug | C37: =C14*C15/1000 | D37: =D14*D15/1000 | E37: =E14*E15/1000 | F37: =F14*F15/1000 | G37: =G14*G15/1000 | H37: =H14*H15/1000 | I37: =I14*I15/1000 | J37: =J14*J15/1000 | ... EJ37: =EJ14*EJ15/1000
A38: Total Lipid Phase Volume | B38: ul | C38: =C15/(C58+1) | D38: =D15/(D58+1) | E38: =E15/(E58+1) | F38: =F15/(F58+1) | G38: =G15/(G58+1) | H38: =H15/(H58+1) | I38: =I15/(I58+1) | J38: =J15/(J58+1) | ... EJ38: =EJ15/(EJ58+1)
A39: Total Nucleic Acid Phase Volume | B39: ul | C39: =C15*C58/(C58+1) | D39: =D15*D58/(D58+1) | E39: =E15*E58/(E58+1) | F39: =F15*F58/(F58+1) | G39: =G15*G58/(G58+1) | H39: =H15*H58/(H58+1) | I39: =I15*I58/(I58+1) | J39: =J15*J58/(J58+1) | ... EJ39: =EJ15*EJ58/(EJ58+1)
A41: Dlin MC3 Percent (molar) | B41: mol % | C41: =C11*C18/(C18+1) | D41: =D11*D18/(D18+1) | E41: =E11*E18/(E18+1) | F41: =F11*F18/(F18+1) | G41: =G11*G18/(G18+1) | H41: =H11*H18/(H18+1) | I41: =I11*I18/(I18+1) | J41: =J11*J18/(J18+1) | ... EJ41: =EJ11*EJ18/(EJ18+1)
A42: Total Dlin MC3 (nmol) | B42: nmol | C42: =C36*C41/100 | D42: =D36*D41/100 | E42: =E36*E41/100 | F42: =F36*F41/100 | G42: =G36*G41/100 | H42: =H36*H41/100 | I42: =I36*I41/100 | J42: =J36*J41/100 | ... EJ42: =EJ36*EJ41/100
A44: Helper Lipid Percent (molar) | B44: mol % | C44: =C11/(1+C18) | D44: =D11/(1+D18) | E44: =E11/(1+E18) | F44: =F11/(1+F18) | G44: =G11/(1+G18) | H44: =H11/(1+H18) | I44: =I11/(1+I18) | J44: =J11/(1+J18) | ... EJ44: =EJ11/(1+EJ18)
A45: Total Helper lipid (nmol) | B45: nmol | C45: =C36*C44/100 | D45: =D36*D44/100 | E45: =E36*E44/100 | F45: =F36*F44/100 | G45: =G36*G44/100 | H45: =H36*H44/100 | I45: =I36*I44/100 | J45: =J36*J44/100 | ... EJ45: =EJ36*EJ44/100
A47: Cholesterol Percent (Molar) | B47: mol % | C47: =(100-C11)*C19/(C19+1) | D47: =(100-D11)*D19/(D19+1) | E47: =(100-E11)*E19/(E19+1) | F47: =(100-F11)*F19/(F19+1) | G47: =(100-G11)*G19/(G19+1) | H47: =(100-H11)*H19/(H19+1) | I47: =(100-I11)*I19/(I19+1) | J47: =(100-J11)*J19/(J19+1) | ... EJ47: =(100-EJ11)*EJ19/(EJ19+1)
A48: Total Cholestrol (mg) | B48: mg | C48: =C36*C47/100*C24/10^6 | D48: =D36*D47/100*D24/10^6 | E48: =E36*E47/100*E24/10^6 | F48: =F36*F47/100*F24/10^6 | G48: =G36*G47/100*G24/10^6 | H48: =H36*H47/100*H24/10^6 | I48: =I36*I47/100*I24/10^6 | J48: =J36*J47/100*J24/10^6 | ... EJ48: =EJ36*EJ47/100*EJ24/10^6
...
